---
title: '221019_TIL'

categories:
  - til
tags:
  - [til]

toc: true
toc_sticky: true

date: 2022-10-19
last_modified_at: 2022-10-19
---

# <span style="color:orange"> 오늘 한 일</span>

- 논리연산자와 옵셔널체이닝 비교
- 널 체크하는 방법, ?? 연산자
- 에러 핸들링 방법
- 에러 버블링에 대한 개념

---

옵셔널 체이닝 ?.

ES11 (ECMAScript 2020) 에 추가됨.
null 또는 undefined을 확인할 때 사용했던,

```javascript
let item = { price: 1 };
const price = item && item.price;
console.log(price);
```

현재 `item`이 반복되는데 이걸 간편하게 줄이기 위해 옵셔널체이닝을 사용할 수 있다.
여기서 사용한 `?.` 라는 옵셔널 체이닝 문법은
item이 있니? 있으면 price 정보에 접근하고, 없으면 접근x라는 뜻이다.

```javascript
let item = { price: 1 };
const price = item?.price;

console.log(price); // 1
```

아래처럼 obj가 계속 반복되는 경우에도 옵셔널 체이닝을 사용하여 심플하게 코드를 나타낼 수 있다.

```javascript
let obj = {
  name: 'puppy',
  owner: { name: '기헌' },
};

function printName(obj) {
  const ownerName = obj && obj.owner && obj.owner.name;
  console.log(ownerName);
}
/** const ownerName = obj.owner.name이라고 한번에 접근
하려고 했다면 없는 것에 계속 접근하려 하기에 에러가 발생한다. */

printName(obj); // 기헌
printName(); // undefined
```

```javascript
let obj = {
  name: 'puppy',
  owner: { name: '기헌' },
};

function printName(obj) {
  const ownerName = obj?.owner?.name;
  console.log(ownerName);
}

printName(obj); // 기헌
```

?? 연산자

|| 논리연산자를 사용하면 falshy 한 모든 것들이 필터링이 되는데,
`null`과 `undefined`인 경우에만 뒤에 값을 실행하거나 하고 싶을 때 ?? 연산자를 사용한다.

num에 0이 없을 때만 -1을 출력하고 싶지만 || 연산자를 사용하면 0도 false이기 때문에 -1이 출력되는 문제가 생긴다.

```javascript
let num = 0;
console.log(num || '-1');
```

아래 코드처럼 ?? 연산자를 사용하면 0이 잘 출력된다. ?? 연산자는 num이 null이거나 undefined 일때만 ?? 연산자 뒤에 적은 코드가 실행되기 때문이다.

```javascript
let num = 0;
console.log(num ?? '-1');
```

<b>에러 핸들링 (에러 처리하는 방법)</b>

```javascript
function readFile(path) {
  throw new Error('파일 경로를 찾을 수 없음');
  return '파일의내용';
}

function processFile(path) {
  const content = readFile(path);
  const result = 'hi ' + content;
  return result;
}

const result = processFile('경로');
console.log(result);
// 에러 발생, throw를 이용해서 에러를 발생시켰기 때문.
```

이렇게 파일의내용을 읽지 못한다고 해서 에러가 나타나면 좋지 않은 UX라고 할 수 있다.
이런 에러들을 처리하는 방법은 : Try , Catch, Finally 가 있다.

```javascript
function readFile(path) {
  throw new Error('파일 경로를 찾을 수 없음');
  return '파일의내용';
}

function processFile(path) {
  let content;
  try {
    content = readFile(path);
  } catch (error) {
    console.log(error.name);
    console.log(error.message);
    console.log(error.stack);
    content = '기본내용';
  } finally {
    console.log('성공하든 실패하든 마지막으로 리소스를 정리할 수 있음');
  }
  const result = 'hi ' + content;
  return result;
}

const result = processFile('경로');
console.log(result);

// hi 기본내용
```

1. 에러가 발생할 수 있는 시작점인 함수호출 부분은 try 안에 작성한다.
2. 함수호출하면서 error가 발생한다면 catch에 작성한 코드가 실행된다.
3. catch가 실행되면서 안에 작성한 내용들을 출력할 수 있고 에러처리를 위한 기본값 설정도 이곳에 해주면 된다.
4. console.log를 name, message, stack 을 호출해서 이름과 메세지, 에러가 발생한 경로 등을
   알 수 있지만 그냥 console.log(error); 만 쳐도 확인이 가능하다.
5. 코드를 실행했는데 에러없이 성공하거나, 에러가 발생하던 상관없이 마지막에 반드시 실행되는 코드는 finally 안에 작성한 코드들이다.
   파일을 마지막에 잘 닫거나 청소해서 끝낼 때 finally에 작성해주면 좋다.

에러 버블링

```javascript
function a() {
  throw new Error('error!');
}

function b() {
  try {
    a();
  } catch (error) {
    console.log(error);
  }
}

function c() {
  b();
}

try {
  c();
} catch (error) {
  console.log('Catched');
}
console.log('done!');
```

코드 전역에 try에서 c를 호출하면 c에서 b를 , b에서 a를 호출하고
a에서 error를 던진다. a의 error는 b로 전파되고, c까지 전파가 된다.

결국엔 c를 호출한 부분에서 catch를 통해 error를 잡을 수 있다.
에러는 최종적으로 호출한 곳까지 계속 전파되기 때문이다.

그래서 전파되는 속성을 이용해서 최종적으로 c에서 잡아줘도 되고
가장 근접한 b에서 잡아도 상관없다. b에서 error를 잡으면 c의 catch가 실행되지 않는다.

catch 에 적은 변수 `error`(아무 이름이나 사용 가능) 는 무슨 일이 일어났는지에 대한 설명이 담긴 에러 객체를 포함한다.

b에서 error를 핸들링하려다가 if문 등을 이용해서 이 error를 처리할 수 없는지 있는지 확인 한 후에 error를 처리 할 수 없는 상황이 나타났을 때,
다시 b에서 error를 던질 수 있고 다른 곳에서 해당 error를 catch 하여 해결할 수 있다.

```javascript
function a() {
	throw new Error('error!');
}

function b() {
	try {
		a();
	} catch('이 에러는 내가 핸들링 할 수 없을 것 같아요') {
		throw error;
	}
}

function c() {
	b();
}

try {
	c();
} catch(error) {
	console.log('Catched');
}
console.log('done!');

```

주의사항은,

1. `try..catch`는 동기적으로 동작한다.

   setTimeout처럼 ‘스케줄 된(scheduled)’ 코드에서 발생한 예외는 `try..catch`에서 잡아낼 수 없다.

   `setTimeout`에 넘겨진 익명 함수는 엔진이 `try..catch`를 떠난 다음에서야 실행되기 때문

   스케줄 된 함수 내부의 예외를 잡으려면, `try..catch`를 반드시 함수 내부에 구현해야 한다.

2. `try..catch`는 오직 런타임 에러에만 동작한다.

   `try..catch`는 실행 가능한(runnable) 코드에만 동작합니다. 실행 가능한 코드는 유효한 자바스크립트 코드를 의미한다.

   중괄호 짝이 안 맞는 것처럼 코드가 문법적으로 잘못된 경우엔 `try..catch`가 동작하지 않는다.

   자바스크립트 엔진은 코드를 읽고 난 후 코드를 실행한다. 코드를 읽는 중에 발생하는 에러는 'parse-time 에러’라고 부르는데, 엔진은 이 코드를 이해할 수 없기 때문에 parse-time 에러는 코드 안에서 복구가 불가능하다.

   `try..catch`는 유효한 코드에서 발생하는 에러만 처리할 수 있다. 이런 에러를 ‘런타임 에러(runtime error)’ 혹은 '예외(exception)'라고 부름.

3. 선택적 ‘catch’ 바인딩

   에러에 대한 자세한 정보가 필요하지 않으면, `catch`
   에서 이를 생략할 수 있다.

```javascript
try {
  // ...
} catch {
  // <-- (err) 없이 쓸 수 있음
  // ...
}
```
